Workbook

Sheet BANKWISE COMLETE DETAILS
A1: ID | B1: Date | C1: Bank_Category | D1: Bank_Name | E1: ATM's Onsite | F1: ATM's Offsite | G1: POS | H1: Micro_ ATM's | I1: Bharath_QR | J1: Upi_QR | K1: Credit_Cards | L1: Debit_Cards | M1: No of CC at POS | N1: Value of CC at POS | O1: No of CC Online Transaction | P1: CC Online Transaction value | Q1: No of other CC Transactions | R1: Value of other CC Transactions | S1: No of Credit CC Withdrawl | T1: Value of CC_Cash Withdrawl | U1: No of DC at POS | V1: Value of DC at POS | W1: No of DC Online Transaction | X1: Value of DC Online Transaction | Y1: No of other DC Transactions | Z1: Value of other DC Transactions | AA1: No of DC _Cash Withdrawl_ATM | AB1: Value_ DC _Cash Withdrawl_ATM | AC1: No of DC _Cash Withdrawl_POS | AD1: Value_DC _Cash Withdrawl_POS | AE1: CC_Transaction Total Value | AF1: DC_Transaction Total value | AG1: Comparision of CC and DC Total value
A2: 0 | B2: 44621 | C2: Small Finance Banks | D2: AU Small Finance Bank | E2: 407 | F2: 3 | G2: 0 | H2: 321 | I2: 0 | J2: 487204 | K2: 169470 | L2: 1935173 | M2: 269852 | N2: 1385159.6 | O2: 197587 | P2: 1881923.7 | Q2: 744 | R2: 364.02 | S2: 4502 | T2: 28352.8 | U2: 247593 | V2: 602474.02 | W2: 184714 | X2: 573932.23 | Y2: 313 | Z2: 3426.59 | AA2: 890008 | AB2: 5886432.8 | AC2: 30 | AD2: 27.6 | AE2: 3295800.1 | AF2: 7066293.2 | AG2: DC High
A3: 1 | B3: 44621 | C3: Payment Banks | D3: Airtel Payments Bank | E3: 0 | F3: 0 | G3: 0 | H3: 0 | I3: 0 | J3: 3208634 | K3: 0 | L3: 1964142 | M3: 0 | N3: 0 | O3: 0 | P3: 0 | Q3: 0 | R3: 0 | S3: 0 | T3: 0 | U3: 0 | V3: 0 | W3: 213807 | X3: 156600.18 | Y3: 0 | Z3: 0 | AA3: 0 | AB3: 0 | AC3: 0 | AD3: 0 | AE3: 0 | AF3: 156600.18 | AG3: DC High
A4: 2 | B4: 44621 | C4: Foreign Banks | D4: American Express | E4: 0 | F4: 0 | G4: 45455 | H4: 0 | I4: 0 | J4: 0 | K4: 1383221 | L4: 0 | M4: 1018513 | N4: 7369321.3 | O4: 3595970 | P4: 25400772 | Q4: 0 | R4: 0 | S4: 0 | T4: 0 | U4: 0 | V4: 0 | W4: 0 | X4: 0 | Y4: 0 | Z4: 0 | AA4: 0 | AB4: 0 | AC4: 0 | AD4: 0 | AE4: 32770093 | AF4: 0 | AG4: CC High
A5: 3 | B5: 44621 | C5: Private Sector Banks | D5: Axis Bank | E5: 5748 | F5: 11174 | G5: 1010244 | H5: 710 | I5: 347644 | J5: 36594577 | K5: 9034829 | L5: 27747647 | M5: 13841270 | N5: 41222880 | O5: 9407975 | P5: 52642163 | Q5: 0 | R5: 0 | S5: 45631 | T5: 185105.56 | U5: 12387481 | V5: 27686319 | W5: 6319140 | X5: 18441050 | Y5: 26208 | Z5: 658186.04 | AA5: 22320612 | AB5: 137931664 | AC5: 0 | AD5: 0 | AE5: 94050149 | AF5: 1.8471722e+08 | AG5: DC High
A6: 4 | B6: 44621 | C6: Private Sector Banks | D6: Bandhan Bank | E6: 466 | F6: 5 | G6: 36339 | H6: 0 | I6: 0 | J6: 0 | K6: 0 | L6: 4966096 | M6: 0 | N6: 0 | O6: 0 | P6: 0 | Q6: 0 | R6: 0 | S6: 0 | T6: 0 | U6: 592668 | V6: 1405190 | W6: 394699 | X6: 918313 | Y6: 0 | Z6: 0 | AA6: 2658287 | AB6: 14003767 | AC6: 27811 | AD6: 27834 | AE6: 0 | AF6: 16355104 | AG6: DC High
A7: 5 | B7: 44621 | C7: Foreign Banks | D7: Bank of America | E7: 0 | F7: 0 | G7: 0 | H7: 0 | I7: 0 | J7: 0 | K7: 21756 | L7: 0 | M7: 27052 | N7: 99065.02 | O7: 12329 | P7: 107630.45 | Q7: 0 | R7: 0 | S7: 0 | T7: 0 | U7: 0 | V7: 0 | W7: 0 | X7: 0 | Y7: 0 | Z7: 0 | AA7: 0 | AB7: 0 | AC7: 0 | AD7: 0 | AE7: 206695.47 | AF7: 0 | AG7: CC High
A8: 6 | B8: 44621 | C8: Public Sector Banks | D8: Bank of Baroda | E8: 8757 | F8: 2730 | G8: 27074 | H8: 35517 | I8: 12378 | J8: 650416 | K8: 1103921 | L8: 74522207 | M8: 1165443 | N8: 3686313.4 | O8: 1085014 | P8: 4499567.6 | Q8: 0 | R8: 0 | S8: 21838 | T8: 101121.59 | U8: 8519967 | V8: 15691963 | W8: 4484921 | X8: 7721120.7 | Y8: 0 | Z8: 0 | AA8: 29706035 | AB8: 1.4045763e+08 | AC8: 2163 | AD8: 1929.46 | AE8: 8287002.5 | AF8: 1.6387264e+08 | AG8: DC High
A9: 7 | B9: 44621 | C9: Public Sector Banks | D9: Bank of India | E9: 2507 | F9: 2751 | G9: 45542 | H9: 10834 | I9: 104 | J9: 353824 | K9: 166751 | L9: 44856938 | M9: 154672 | N9: 508947.35 | O9: 122496 | P9: 335866.87 | Q9: 0 | R9: 0 | S9: 10184 | T9: 59089.17 | U9: 5121057 | V9: 8817597.6 | W9: 3213983 | X9: 4057260.8 | Y9: 0 | Z9: 0 | AA9: 18870699 | AB9: 74143941 | AC9: 16653 | AD9: 16314.49 | AE9: 903903.39 | AF9: 87035114 | AG9: DC High
A10: 8 | B10: 44621 | C10: Public Sector Banks | D10: Bank of Maharashtra | E10: 1694 | F10: 434 | G10: 2795 | H10: 0 | I10: 355014 | J10: 433713 | K10: 77677 | L10: 12264810 | M10: 96808 | N10: 407564.18 | O10: 0 | P10: 0 | Q10: 0 | R10: 0 | S10: 1225 | T10: 5727.86 | U10: 2889361 | V10: 4340817.3 | W10: 1131118 | X10: 1477836.4 | Y10: 10610 | Z10: 128268.9 | AA10: 7541893 | AB10: 32295602 | AC10: 0 | AD10: 0 | AE10: 413292.04 | AF10: 38242525 | AG10: DC High
A11: 9 | B11: 44621 | C11: Foreign Banks | D11: Barclays Bank | E11: 0 | F11: 0 | G11: 0 | H11: 0 | I11: 1 | J11: 0 | K11: 0 | L11: 1736 | M11: 0 | N11: 0 | O11: 0 | P11: 0 | Q11: 0 | R11: 0 | S11: 0 | T11: 0 | U11: 100 | V11: 907.05 | W11: 32 | X11: 28.32 | Y11: 0 | Z11: 0 | AA11: 401 | AB11: 3499.95 | AC11: 0 | AD11: 0 | AE11: 0 | AF11: 4435.32 | AG11: DC High
A12: 10 | B12: 44621 | C12: Public Sector Banks | D12: Canara Bank | E12: 8071 | F12: 4139 | G12: 50032 | H12: 8096 | I12: 69 | J12: 1264169 | K12: 927694 | L12: 46459485 | M12: 662053 | N12: 1715137 | O12: 305102 | P12: 965897.95 | Q12: 0 | R12: 0 | S12: 56673 | T12: 284861.14 | U12: 10233195 | V12: 19323217 | W12: 4791270 | X12: 7906774.6 | Y12: 5255 | Z12: 85017.56 | AA12: 32586175 | AB12: 1.4880952e+08 | AC12: 2798 | AD12: 2467.67 | AE12: 2965896.1 | AF12: 1.7612699e+08 | AG12: DC High
A13: 11 | B13: 44621 | C13: Small Finance Banks | D13: Capital Small Finance Bank | E13: 161 | F13: 2 | G13: 0 | H13: 0 | I13: 0 | J13: 0 | K13: 0 | L13: 183510 | M13: 0 | N13: 0 | O13: 0 | P13: 0 | Q13: 0 | R13: 0 | S13: 0 | T13: 0 | U13: 49955 | V13: 135511.46 | W13: 20448 | X13: 40847.14 | Y13: 0 | Z13: 0 | AA13: 129173 | AB13: 699054.17 | AC13: 0 | AD13: 0 | AE13: 0 | AF13: 875412.77 | AG13: DC High
... A31: 29 | B31: 44621 | C31: Private Sector Banks | D31: IDFC First Bank | E31: 505 | F31: 214 | G31: 26560 | H31: 11522 | I31: 0 | J31: 38079 | K31: 799219 | L31: 4076204 | M31: 1367730 | N31: 4899089.8 | O31: 1325904 | P31: 7584241 | Q31: 0 | R31: 0 | S31: 11799 | T31: 43601.4 | U31: 1414101 | V31: 2015650.3 | W31: 508390 | X31: 1428377.4 | Y31: 0 | Z31: 0 | AA31: 3103785 | AB31: 12878265 | AC31: 0 | AD31: 0 | AE31: 12526932 | AF31: 16322293 | AG31: DC High
A32: 30 | B32: 44621 | C32: Payment Banks | D32: India Post Payments Bank | E32: 0 | F32: 0 | G32: 0 | H32: 135092 | I32: 0 | J32: 0 | K32: 0 | L32: 4788986 | U32: 0 | V32: 0 | W32: 389128 | X32: 240570.97 | Y32: 0 | Z32: 0 | AA32: 0 | AB32: 0 | AC32: 0 | AD32: 0 | AE32: 0 | AF32: 240570.97 | AG32: DC High
A33: 31 | B33: 44621 | C33: Public Sector Banks | D33: Indian Bank | E33: 4299 | F33: 626 | G33: 14981 | H33: 9322 | I33: 0 | J33: 356603 | K33: 154342 | L33: 26961021 | M33: 129022 | N33: 378092.66 | O33: 73904 | P33: 237320.61 | Q33: 0 | R33: 0 | S33: 3511 | T33: 22363.77 | U33: 6087414 | V33: 10556404 | W33: 3068094 | X33: 4255370.5 | Y33: 6422 | Z33: 102363.19 | AA33: 21419031 | AB33: 99716222 | AC33: 32990 | AD33: 32410.1 | AE33: 637777.04 | AF33: 1.1466277e+08 | AG33: DC High
A34: 32 | B34: 44621 | C34: Public Sector Banks | D34: Indian Overseas Bank | E34: 2742 | F34: 613 | G34: 0 | H34: 0 | I34: 0 | J34: 81152 | K34: 74083 | L34: 20508718 | M34: 59749 | N34: 142499.79 | O34: 26426 | P34: 63550.33 | Q34: 0 | R34: 0 | S34: 867 | T34: 4013.25 | U34: 3664568 | V34: 6294023.6 | W34: 1386870 | X34: 2078848.1 | Y34: 0 | Z34: 0 | AA34: 15137144 | AB34: 64870005 | AC34: 0 | AD34: 0 | AE34: 210063.37 | AF34: 73242877 | AG34: DC High
A35: 33 | B35: 44621 | C35: Private Sector Banks | D35: IndusInd Bank | E35: 1492 | F35: 1275 | G35: 220160 | H35: 164 | I35: 35908 | J35: 68715 | K35: 1880393 | L35: 6910699 | M35: 2254748 | N35: 10802314 | O35: 2542328 | P35: 45782776 | Q35: 0 | R35: 0 | S35: 18246 | T35: 92623.22 | U35: 1758336 | V35: 3496811.5 | W35: 1170562 | X35: 3541165 | Y35: 1017 | Z35: 83630.76 | AA35: 5623319 | AB35: 27508948 | AC35: 0 | AD35: 0 | AE35: 56677714 | AF35: 34630555 | AG35: CC High
A36: 34 | B36: 44621 | C36: Private Sector Banks | D36: Jammu & Kashmir Bank | E36: 840 | F36: 613 | G36: 10948 | H36: 945 | I36: 0 | J36: 32064 | K36: 82096 | L36: 3457424 | M36: 145394 | N36: 910884.73 | O36: 112520 | P36: 287848.82 | Q36: 0 | R36: 0 | S36: 7074 | T36: 27799 | U36: 1236554 | V36: 2919949.8 | W36: 3462733 | X36: 1602698.1 | Y36: 0 | Z36: 0 | AA36: 6298900 | AB36: 31721953 | AC36: 6 | AD36: 5.9 | AE36: 1226532.6 | AF36: 36244607 | AG36: DC High
A37: 35 | B37: 44621 | C37: Small Finance Banks | D37: Jana Small Finance Bank | E37: 65 | F37: 2 | G37: 0 | H37: 164 | I37: 0 | J37: 493552 | K37: 0 | L37: 2345835 | M37: 0 | N37: 0 | O37: 0 | P37: 0 | Q37: 0 | R37: 0 | S37: 0 | T37: 0 | U37: 66760 | V37: 93390.33 | W37: 17613 | X37: 33770.25 | Y37: 0 | Z37: 0 | AA37: 311964 | AB37: 1532327.8 | AC37: 0 | AD37: 0 | AE37: 0 | AF37: 1659488.4 | AG37: DC High
A38: 36 | B38: 44621 | C38: Payment Banks | D38: Jio Payments Bank | E38: 0 | F38: 0 | G38: 0 | H38: 0 | I38: 0 | J38: 0 | K38: 0 | L38: 0 | M38: 0 | N38: 0 | O38: 0 | P38: 0 | Q38: 0 | R38: 0 | S38: 0 | T38: 0 | U38: 0 | V38: 0 | W38: 0 | X38: 0 | Y38: 0 | Z38: 0 | AA38: 0 | AB38: 0 | AC38: 0 | AD38: 0 | AE38: 0 | AF38: 0 | AG38: DC High
A39: 37 | B39: 44621 | C39: Private Sector Banks | D39: Karnataka Bank | E39: 819 | F39: 629 | G39: 9312 | H39: 0 | I39: 0 | J39: 28511 | K39: 0 | L39: 5113093 | M39: 0 | N39: 0 | O39: 0 | P39: 0 | Q39: 0 | R39: 0 | S39: 0 | T39: 0 | U39: 1892513 | V39: 2748661.3 | W39: 491340 | X39: 758620.53 | Y39: 0 | Z39: 0 | AA39: 4554359 | AB39: 20083708 | AC39: 0 | AD39: 0 | AE39: 0 | AF39: 23590990 | AG39: DC High
A40: 38 | B40: 44621 | C40: Private Sector Banks | D40: Karur Vysya Bank | E40: 1362 | F40: 861 | G40: 8745 | H40: 0 | I40: 0 | J40: 14391 | K40: 6691 | L40: 4066117 | M40: 15483 | N40: 76127.51 | O40: 3962 | P40: 40563.18 | Q40: 0 | R40: 0 | S40: 284 | T40: 2103.86 | U40: 2047824 | V40: 3988487.3 | W40: 557806 | X40: 1301886 | Y40: 11382 | Z40: 235964.58 | AA40: 5308872 | AB40: 25548661 | AC40: 0 | AD40: 0 | AE40: 118794.55 | AF40: 31074999 | AG40: DC High
A41: 39 | B41: 44621 | C41: Private Sector Banks | D41: Kotak Mahindra Bank | E41: 1385 | F41: 1314 | G41: 56334 | H41: 5020 | I41: 21849 | J41: 236089 | K41: 3196377 | L41: 23530754 | M41: 3697560 | N41: 11786280 | O41: 3112625 | P41: 16913066 | Q41: 0 | R41: 0 | S41: 32856 | T41: 134435.46 | U41: 5375357 | V41: 9419902.1 | W41: 4267271 | X41: 9021503.3 | Y41: 0 | Z41: 0 | AA41: 10389295 | AB41: 47795916 | AC41: 0 | AD41: 0 | AE41: 28833782 | AF41: 66237322 | AG41: DC High
A42: 40 | B42: 44621 | C42: Payment Banks | D42: NSDL Payments Bank | E42: 0 | F42: 0 | G42: 0 | H42: 30397 | I42: 0 | J42: 0 | K42: 0 | L42: 334371 | M42: 0 | N42: 0 | O42: 0 | P42: 0 | Q42: 0 | R42: 0 | S42: 0 | T42: 0 | U42: 903 | V42: 864.01 | W42: 23785 | X42: 11512.9 | Y42: 0 | Z42: 0 | AA42: 3801 | AB42: 15699.67 | AC42: 0 | AD42: 0 | AE42: 0 | AF42: 28076.58 | AG42: DC High
A43: 41 | B43: 44621 | C43: Small Finance Banks | D43: North East Small Finance Bank | E43: 8 | F43: 1 | G43: 0 | H43: 0 | I43: 0 | J43: 0 | K43: 0 | L43: 303473 | M43: 0 | N43: 0 | O43: 0 | P43: 0 | Q43: 0 | R43: 0 | S43: 0 | T43: 0 | U43: 19390 | V43: 26156.09 | W43: 0 | X43: 0 | Y43: 0 | Z43: 0 | AA43: 49452 | AB43: 202993.29 | AC43: 0 | AD43: 0 | AE43: 0 | AF43: 229149.38 | AG43: DC High
A44: 42 | B44: 44621 | C44: Payment Banks | D44: Paytm Payments Bank | E44: 1 | F44: 70 | G44: 403006 | H44: 0 | I44: 0 | J44: 21585576 | K44: 0 | L44: 36619887 | M44: 0 | N44: 0 | O44: 0 | P44: 0 | Q44: 0 | R44: 0 | S44: 0 | T44: 0 | U44: 811299 | V44: 954816.09 | W44: 1830442 | X44: 2084776.1 | Y44: 0 | Z44: 0 | AA44: 2669476 | AB44: 9729090.6 | AC44: 0 | AD44: 0 | AE44: 0 | AF44: 12768683 | AG44: DC High
... A89: 87 | B89: 44652 | C89: Private Sector Banks | D89: IDFC First Bank | E89: 538 | F89: 217 | G89: 27379 | H89: 11522 | I89: 0 | J89: 38079 | K89: 856394 | L89: 4183935 | M89: 1387038 | N89: 4889459.8 | O89: 1233117 | P89: 7122440.9 | Q89: 0 | R89: 0 | S89: 11612 | T89: 42028.3 | U89: 1421423 | V89: 2199060.3 | W89: 475556 | X89: 1271460.6 | Y89: 0 | Z89: 0 | AA89: 3069190 | AB89: 13038809 | AC89: 0 | AD89: 0 | AE89: 12053929 | AF89: 16509330 | AG89: DC High
A90: 88 | B90: 44652 | C90: Payment Banks | D90: India Post Payments Bank | E90: 0 | F90: 0 | G90: 0 | H90: 132120 | I90: 0 | J90: 0 | K90: 0 | L90: 5112794 | U90: 0 | V90: 0 | W90: 447729 | X90: 247186.01 | Y90: 0 | Z90: 0 | AA90: 0 | AB90: 0 | AC90: 0 | AD90: 0 | AE90: 0 | AF90: 247186.01 | AG90: DC High
A91: 89 | B91: 44652 | C91: Public Sector Banks | D91: Indian Bank | E91: 4243 | F91: 596 | G91: 14905 | H91: 9657 | I91: 0 | J91: 362545 | K91: 154353 | L91: 27095159 | M91: 130521 | N91: 390560.15 | O91: 70857 | P91: 217746.46 | Q91: 0 | R91: 0 | S91: 2882 | T91: 18423.06 | U91: 6090631 | V91: 11066118 | W91: 2917766 | X91: 3853086.6 | Y91: 5916 | Z91: 90230.43 | AA91: 20657436 | AB91: 97670638 | AC91: 34105 | AD91: 33520.06 | AE91: 626729.67 | AF91: 1.1271359e+08 | AG91: DC High
A92: 90 | B92: 44652 | C92: Public Sector Banks | D92: Indian Overseas Bank | E92: 2732 | F92: 624 | G92: 0 | H92: 0 | I92: 0 | J92: 85158 | K92: 74442 | L92: 14617281 | M92: 60881 | N92: 147019.9 | O92: 26039 | P92: 58287.89 | Q92: 0 | R92: 0 | S92: 756 | T92: 3552.7 | U92: 3752265 | V92: 6664726.3 | W92: 1294963 | X92: 1862035.1 | Y92: 0 | Z92: 0 | AA92: 14720895 | AB92: 64039461 | AC92: 0 | AD92: 0 | AE92: 208860.49 | AF92: 72566222 | AG92: DC High
A93: 91 | B93: 44652 | C93: Private Sector Banks | D93: IndusInd Bank | E93: 1499 | F93: 1266 | G93: 218935 | H93: 164 | I93: 35950 | J93: 42160 | K93: 1922608 | L93: 7067037 | M93: 2266407 | N93: 10555163 | O93: 2398443 | P93: 41233030 | Q93: 0 | R93: 0 | S93: 17751 | T93: 89261.33 | U93: 1759985 | V93: 3639272.2 | W93: 1147265 | X93: 3150072.6 | Y93: 1077 | Z93: 84399.06 | AA93: 5008947 | AB93: 26385222 | AC93: 0 | AD93: 0 | AE93: 51877454 | AF93: 33258966 | AG93: CC High
A94: 92 | B94: 44652 | C94: Private Sector Banks | D94: Jammu & Kashmir Bank | E94: 840 | F94: 614 | G94: 10681 | H94: 945 | I94: 0 | J94: 34066 | K94: 82098 | L94: 3507929 | M94: 124381 | N94: 814568.34 | O94: 106545 | P94: 249940.23 | Q94: 0 | R94: 0 | S94: 5726 | T94: 23724 | U94: 1194471 | V94: 2915260.6 | W94: 3811305 | X94: 1575033.7 | Y94: 0 | Z94: 0 | AA94: 6381892 | AB94: 34658843 | AC94: 7 | AD94: 6.06 | AE94: 1088232.6 | AF94: 39149143 | AG94: DC High
A95: 93 | B95: 44652 | C95: Small Finance Banks | D95: Jana Small Finance Bank | E95: 65 | F95: 2 | G95: 0 | H95: 164 | I95: 0 | J95: 493717 | K95: 0 | L95: 2373395 | M95: 0 | N95: 0 | O95: 0 | P95: 0 | Q95: 0 | R95: 0 | S95: 0 | T95: 0 | U95: 66178 | V95: 98203.7 | W95: 17011 | X95: 29900.92 | Y95: 0 | Z95: 0 | AA95: 276500 | AB95: 1339812.9 | AC95: 0 | AD95: 0 | AE95: 0 | AF95: 1467917.5 | AG95: DC High
A96: 94 | B96: 44652 | C96: Payment Banks | D96: Jio Payments Bank | E96: 0 | F96: 0 | G96: 0 | H96: 0 | I96: 0 | J96: 0 | K96: 0 | L96: 0 | M96: 0 | N96: 0 | O96: 0 | P96: 0 | Q96: 0 | R96: 0 | S96: 0 | T96: 0 | U96: 0 | V96: 0 | W96: 0 | X96: 0 | Y96: 0 | Z96: 0 | AA96: 0 | AB96: 0 | AC96: 0 | AD96: 0 | AE96: 0 | AF96: 0 | AG96: DC High
A97: 95 | B97: 44652 | C97: Private Sector Banks | D97: Karnataka Bank | E97: 825 | F97: 626 | G97: 9382 | H97: 0 | I97: 0 | J97: 30120 | K97: 0 | L97: 5144007 | M97: 0 | N97: 0 | O97: 0 | P97: 0 | Q97: 0 | R97: 0 | S97: 0 | T97: 0 | U97: 1862575 | V97: 2820280.7 | W97: 424515 | X97: 674887.41 | Y97: 0 | Z97: 0 | AA97: 4316271 | AB97: 19085224 | AC97: 0 | AD97: 0 | AE97: 0 | AF97: 22580393 | AG97: DC High
A98: 96 | B98: 44652 | C98: Private Sector Banks | D98: Karur Vysya Bank | E98: 1363 | F98: 856 | G98: 8669 | H98: 0 | I98: 0 | J98: 14532 | K98: 6930 | L98: 4063846 | M98: 18705 | N98: 82484.18 | O98: 4367 | P98: 38383.84 | Q98: 0 | R98: 0 | S98: 334 | T98: 2364.5 | U98: 2046250 | V98: 4143801.8 | W98: 543058 | X98: 1143808.7 | Y98: 10105 | Z98: 198918.61 | AA98: 5104165 | AB98: 24668707 | AC98: 0 | AD98: 0 | AE98: 123232.52 | AF98: 30155236 | AG98: DC High
A99: 97 | B99: 44652 | C99: Private Sector Banks | D99: Kotak Mahindra Bank | E99: 1384 | F99: 1319 | G99: 56647 | H99: 5483 | I99: 22653 | J99: 244101 | K99: 3425409 | L99: 23883034 | M99: 3845081 | N99: 11754124 | O99: 3129115 | P99: 16658320 | Q99: 0 | R99: 0 | S99: 34216 | T99: 135879.13 | U99: 5384725 | V99: 9284625.1 | W99: 4116930 | X99: 7907962.2 | Y99: 0 | Z99: 0 | AA99: 10389247 | AB99: 48266618 | AC99: 0 | AD99: 0 | AE99: 28548323 | AF99: 65459205 | AG99: DC High
A100: 98 | B100: 44652 | C100: Payment Banks | D100: NSDL Payments Bank | E100: 0 | F100: 0 | G100: 0 | H100: 36061 | I100: 0 | J100: 0 | K100: 0 | L100: 349949 | M100: 0 | N100: 0 | O100: 0 | P100: 0 | Q100: 0 | R100: 0 | S100: 0 | T100: 0 | U100: 824 | V100: 892.78 | W100: 20435 | X100: 9925.78 | Y100: 0 | Z100: 0 | AA100: 3787 | AB100: 16145.66 | AC100: 0 | AD100: 0 | AE100: 0 | AF100: 26964.22 | AG100: DC High
A101: 99 | B101: 44652 | C101: Small Finance Banks | D101: North East Small Finance Bank | E101: 8 | F101: 1 | G101: 0 | H101: 0 | I101: 0 | J101: 0 | K101: 0 | L101: 306569 | M101: 0 | N101: 0 | O101: 0 | P101: 0 | Q101: 0 | R101: 0 | S101: 0 | T101: 0 | U101: 18858 | V101: 24887.08 | W101: 0 | X101: 0 | Y101: 0 | Z101: 0 | AA101: 49076 | AB101: 198883.92 | AC101: 0 | AD101: 0 | AE101: 0 | AF101: 223771 | AG101: DC High
...

Sheet Dim_Bank
A1: ID | B1: Bank_Category | C1: Bank_Name
A2: 0 | B2: Small Finance Banks | C2: AU Small Finance Bank
A3: 1 | B3: Payment Banks | C3: Airtel Payments Bank
A4: 2 | B4: Foreign Banks | C4: American Express
A5: 3 | B5: Private Sector Banks | C5: Axis Bank
A6: 4 | B6: Private Sector Banks | C6: Bandhan Bank
A7: 5 | B7: Foreign Banks | C7: Bank of America
A8: 6 | B8: Public Sector Banks | C8: Bank of Baroda
A9: 7 | B9: Public Sector Banks | C9: Bank of India
A10: 8 | B10: Public Sector Banks | C10: Bank of Maharashtra
A11: 9 | B11: Foreign Banks | C11: Barclays Bank
A12: 10 | B12: Public Sector Banks | C12: Canara Bank
A13: 11 | B13: Small Finance Banks | C13: Capital Small Finance Bank
... A2672: 2670 | B2672: Private Sector Banks | C2672: Yes Bank

Sheet Dim_Date
A1: Date | B1: Year | C1: Month_name | D1: Month_no | E1: Financial_year | F1: Quarterly | G1: Financial year month_no
A2: 44621 | B2: =YEAR(A2) -> 2022 | C2: =TEXT(A2,"mmmm") -> March | D2: =MONTH(A2) -> 3 | E2: =IF(MONTH(A2)>3, "FY " & YEAR(A2) & "-" & RIGHT(YEAR(A2)+1, 2), "FY " & YEAR(A2)-1 & "-" & RIGHT(YEAR(A2), 2)) -> FY 2021-22 | F2: ="Q" & ROUNDUP(MONTH(A2)/3,0) -> Q1 | G2: =IF(MONTH(A2)>=4, MONTH(A2)-3, MONTH(A2)+9) -> 12
A3: 44621 | B3: =YEAR(A3) -> 2022 | C3: =TEXT(A3,"mmmm") -> March | D3: =MONTH(A3) -> 3 | E3: =IF(MONTH(A3)>3, "FY " & YEAR(A3) & "-" & RIGHT(YEAR(A3)+1, 2), "FY " & YEAR(A3)-1 & "-" & RIGHT(YEAR(A3), 2)) -> FY 2021-22 | F3: ="Q" & ROUNDUP(MONTH(A3)/3,0) -> Q1 | G3: =IF(MONTH(A3)>=4, MONTH(A3)-3, MONTH(A3)+9) -> 12
A4: 44621 | B4: =YEAR(A4) -> 2022 | C4: =TEXT(A4,"mmmm") -> March | D4: =MONTH(A4) -> 3 | E4: =IF(MONTH(A4)>3, "FY " & YEAR(A4) & "-" & RIGHT(YEAR(A4)+1, 2), "FY " & YEAR(A4)-1 & "-" & RIGHT(YEAR(A4), 2)) -> FY 2021-22 | F4: ="Q" & ROUNDUP(MONTH(A4)/3,0) -> Q1 | G4: =IF(MONTH(A4)>=4, MONTH(A4)-3, MONTH(A4)+9) -> 12
A5: 44621 | B5: =YEAR(A5) -> 2022 | C5: =TEXT(A5,"mmmm") -> March | D5: =MONTH(A5) -> 3 | E5: =IF(MONTH(A5)>3, "FY " & YEAR(A5) & "-" & RIGHT(YEAR(A5)+1, 2), "FY " & YEAR(A5)-1 & "-" & RIGHT(YEAR(A5), 2)) -> FY 2021-22 | F5: ="Q" & ROUNDUP(MONTH(A5)/3,0) -> Q1 | G5: =IF(MONTH(A5)>=4, MONTH(A5)-3, MONTH(A5)+9) -> 12
A6: 44621 | B6: =YEAR(A6) -> 2022 | C6: =TEXT(A6,"mmmm") -> March | D6: =MONTH(A6) -> 3 | E6: =IF(MONTH(A6)>3, "FY " & YEAR(A6) & "-" & RIGHT(YEAR(A6)+1, 2), "FY " & YEAR(A6)-1 & "-" & RIGHT(YEAR(A6), 2)) -> FY 2021-22 | F6: ="Q" & ROUNDUP(MONTH(A6)/3,0) -> Q1 | G6: =IF(MONTH(A6)>=4, MONTH(A6)-3, MONTH(A6)+9) -> 12
A7: 44621 | B7: =YEAR(A7) -> 2022 | C7: =TEXT(A7,"mmmm") -> March | D7: =MONTH(A7) -> 3 | E7: =IF(MONTH(A7)>3, "FY " & YEAR(A7) & "-" & RIGHT(YEAR(A7)+1, 2), "FY " & YEAR(A7)-1 & "-" & RIGHT(YEAR(A7), 2)) -> FY 2021-22 | F7: ="Q" & ROUNDUP(MONTH(A7)/3,0) -> Q1 | G7: =IF(MONTH(A7)>=4, MONTH(A7)-3, MONTH(A7)+9) -> 12
A8: 44621 | B8: =YEAR(A8) -> 2022 | C8: =TEXT(A8,"mmmm") -> March | D8: =MONTH(A8) -> 3 | E8: =IF(MONTH(A8)>3, "FY " & YEAR(A8) & "-" & RIGHT(YEAR(A8)+1, 2), "FY " & YEAR(A8)-1 & "-" & RIGHT(YEAR(A8), 2)) -> FY 2021-22 | F8: ="Q" & ROUNDUP(MONTH(A8)/3,0) -> Q1 | G8: =IF(MONTH(A8)>=4, MONTH(A8)-3, MONTH(A8)+9) -> 12
A9: 44621 | B9: =YEAR(A9) -> 2022 | C9: =TEXT(A9,"mmmm") -> March | D9: =MONTH(A9) -> 3 | E9: =IF(MONTH(A9)>3, "FY " & YEAR(A9) & "-" & RIGHT(YEAR(A9)+1, 2), "FY " & YEAR(A9)-1 & "-" & RIGHT(YEAR(A9), 2)) -> FY 2021-22 | F9: ="Q" & ROUNDUP(MONTH(A9)/3,0) -> Q1 | G9: =IF(MONTH(A9)>=4, MONTH(A9)-3, MONTH(A9)+9) -> 12
A10: 44621 | B10: =YEAR(A10) -> 2022 | C10: =TEXT(A10,"mmmm") -> March | D10: =MONTH(A10) -> 3 | E10: =IF(MONTH(A10)>3, "FY " & YEAR(A10) & "-" & RIGHT(YEAR(A10)+1, 2), "FY " & YEAR(A10)-1 & "-" & RIGHT(YEAR(A10), 2)) -> FY 2021-22 | F10: ="Q" & ROUNDUP(MONTH(A10)/3,0) -> Q1 | G10: =IF(MONTH(A10)>=4, MONTH(A10)-3, MONTH(A10)+9) -> 12
A11: 44621 | B11: =YEAR(A11) -> 2022 | C11: =TEXT(A11,"mmmm") -> March | D11: =MONTH(A11) -> 3 | E11: =IF(MONTH(A11)>3, "FY " & YEAR(A11) & "-" & RIGHT(YEAR(A11)+1, 2), "FY " & YEAR(A11)-1 & "-" & RIGHT(YEAR(A11), 2)) -> FY 2021-22 | F11: ="Q" & ROUNDUP(MONTH(A11)/3,0) -> Q1 | G11: =IF(MONTH(A11)>=4, MONTH(A11)-3, MONTH(A11)+9) -> 12
A12: 44621 | B12: =YEAR(A12) -> 2022 | C12: =TEXT(A12,"mmmm") -> March | D12: =MONTH(A12) -> 3 | E12: =IF(MONTH(A12)>3, "FY " & YEAR(A12) & "-" & RIGHT(YEAR(A12)+1, 2), "FY " & YEAR(A12)-1 & "-" & RIGHT(YEAR(A12), 2)) -> FY 2021-22 | F12: ="Q" & ROUNDUP(MONTH(A12)/3,0) -> Q1 | G12: =IF(MONTH(A12)>=4, MONTH(A12)-3, MONTH(A12)+9) -> 12
A13: 44621 | B13: =YEAR(A13) -> 2022 | C13: =TEXT(A13,"mmmm") -> March | D13: =MONTH(A13) -> 3 | E13: =IF(MONTH(A13)>3, "FY " & YEAR(A13) & "-" & RIGHT(YEAR(A13)+1, 2), "FY " & YEAR(A13)-1 & "-" & RIGHT(YEAR(A13), 2)) -> FY 2021-22 | F13: ="Q" & ROUNDUP(MONTH(A13)/3,0) -> Q1 | G13: =IF(MONTH(A13)>=4, MONTH(A13)-3, MONTH(A13)+9) -> 12
... A2672: 45901 | B2672: =YEAR(A2672) -> 2025 | C2672: =TEXT(A2672,"mmmm") -> September | D2672: =MONTH(A2672) -> 9 | E2672: =IF(MONTH(A2672)>3, "FY " & YEAR(A2672) & "-" & RIGHT(YEAR(A2672)+1, 2), "FY " & YEAR(A2672)-1 & "-" & RIGHT(YEAR(A2672), 2)) -> FY 2025-26 | F2672: ="Q" & ROUNDUP(MONTH(A2672)/3,0) -> Q3 | G2672: =IF(MONTH(A2672)>=4, MONTH(A2672)-3, MONTH(A2672)+9) -> 6

Sheet Service_Banks
A1: Service type | B1: Total
A2: ATM Onsite | B2: =COUNTIF('BANKWISE COMLETE DETAILS'!$E$2:$E$2672,">0") -> 2071
A3: pos | B3: =COUNTIF('BANKWISE COMLETE DETAILS'!$G$2:$G$2672,">0") -> 1454
A4: micro ATM | B4: =COUNTIF('BANKWISE COMLETE DETAILS'!$H$2:$H$2672,">0") -> 1418
A5: Bharath_QR | B5: =COUNTIF('BANKWISE COMLETE DETAILS'!$I$2:$I$2672,">0") -> 978
A6: UPI_QR | B6: =COUNTIF('BANKWISE COMLETE DETAILS'!$J$2:$J$2672,">0") -> 1668
A7: Credit_Cards Outstanding | B7: =COUNTIF('BANKWISE COMLETE DETAILS'!$K$2:$K$2672,">0") -> 1516
A8: Debit_Cards Outstanding | B8: =COUNTIF('BANKWISE COMLETE DETAILS'!$L$2:$L$2672,">0") -> 2515

Sheet Public Sector Bank
A1: ID | B1: Date | C1: Bank_Category | D1: Bank_Name | E1: ATM's Onsite | F1: ATM's Offsite | G1: POS | H1: Micro_ ATM's | I1: Bharath_QR | J1: Upi_QR | K1: Credit_Cards | L1: Debit_Cards | M1: No of CC at POS | N1: Value of CC at POS | O1: No of CC Online Transaction | P1: CC Online Transaction value | Q1: No of other CC Transactions | R1: Value of other CC Transactions | S1: No of Credit CC Withdrawl | T1: Value of CC_Cash Withdrawl | U1: No of DC at POS | V1: Value of DC at POS | W1: No ofDC Online Transaction | X1: Value of DC Online Transaction | Y1: No of other DC Transactions | Z1: Value of other DC Transactions | AA1: No of DC _Cash Withdrawl_ATM | AB1: Value_ DC _Cash Withdrawl_ATM | AC1: No of DC _Cash Withdrawl_POS | AD1: Value_DC _Cash Withdrawl_POS | AE1: CC_Transaction Total Value | AF1: DC_Transaction Total value | AG1: Comparision of CC and DC Total value
A2: 6 | B2: 44621 | C2: Public Sector Banks | D2: Bank of Baroda | E2: 8757 | F2: 2730 | G2: 27074 | H2: 35517 | I2: 12378 | J2: 650416 | K2: 1103921 | L2: 74522207 | M2: 1165443 | N2: 3686313.4 | O2: 1085014 | P2: 4499567.6 | Q2: 0 | R2: 0 | S2: 21838 | T2: 101121.59 | U2: 8519967 | V2: 15691963 | W2: 4484921 | X2: 7721120.7 | Y2: 0 | Z2: 0 | AA2: 29706035 | AB2: 1.4045763e+08 | AC2: 2163 | AD2: 1929.46 | AE2: 8287002.5 | AF2: 1.6387264e+08 | AG2: DC High
A3: 7 | B3: 44621 | C3: Public Sector Banks | D3: Bank of India | E3: 2507 | F3: 2751 | G3: 45542 | H3: 10834 | I3: 104 | J3: 353824 | K3: 166751 | L3: 44856938 | M3: 154672 | N3: 508947.35 | O3: 122496 | P3: 335866.87 | Q3: 0 | R3: 0 | S3: 10184 | T3: 59089.17 | U3: 5121057 | V3: 8817597.6 | W3: 3213983 | X3: 4057260.8 | Y3: 0 | Z3: 0 | AA3: 18870699 | AB3: 74143941 | AC3: 16653 | AD3: 16314.49 | AE3: 903903.39 | AF3: 87035114 | AG3: DC High
A4: 8 | B4: 44621 | C4: Public Sector Banks | D4: Bank of Maharashtra | E4: 1694 | F4: 434 | G4: 2795 | H4: 0 | I4: 355014 | J4: 433713 | K4: 77677 | L4: 12264810 | M4: 96808 | N4: 407564.18 | O4: 0 | P4: 0 | Q4: 0 | R4: 0 | S4: 1225 | T4: 5727.86 | U4: 2889361 | V4: 4340817.3 | W4: 1131118 | X4: 1477836.4 | Y4: 10610 | Z4: 128268.9 | AA4: 7541893 | AB4: 32295602 | AC4: 0 | AD4: 0 | AE4: 413292.04 | AF4: 38242525 | AG4: DC High
A5: 10 | B5: 44621 | C5: Public Sector Banks | D5: Canara Bank | E5: 8071 | F5: 4139 | G5: 50032 | H5: 8096 | I5: 69 | J5: 1264169 | K5: 927694 | L5: 46459485 | M5: 662053 | N5: 1715137 | O5: 305102 | P5: 965897.95 | Q5: 0 | R5: 0 | S5: 56673 | T5: 284861.14 | U5: 10233195 | V5: 19323217 | W5: 4791270 | X5: 7906774.6 | Y5: 5255 | Z5: 85017.56 | AA5: 32586175 | AB5: 1.4880952e+08 | AC5: 2798 | AD5: 2467.67 | AE5: 2965896.1 | AF5: 1.7612699e+08 | AG5: DC High
A6: 13 | B6: 44621 | C6: Public Sector Banks | D6: Central Bank of India | E6: 2389 | F6: 587 | G6: 3957 | H6: 8015 | I6: 7543 | J6: 175363 | K6: 0 | L6: 30197222 | M6: 0 | N6: 0 | O6: 0 | P6: 0 | Q6: 0 | R6: 0 | S6: 0 | T6: 0 | U6: 2618263 | V6: 5511293.5 | W6: 486339 | X6: 946614.01 | Y6: 0 | Z6: 0 | AA6: 9716712 | AB6: 43780949 | AC6: 9887 | AD6: 9946.03 | AE6: 0 | AF6: 50248803 | AG6: DC High
A7: 31 | B7: 44621 | C7: Public Sector Banks | D7: Indian Bank | E7: 4299 | F7: 626 | G7: 14981 | H7: 9322 | I7: 0 | J7: 356603 | K7: 154342 | L7: 26961021 | M7: 129022 | N7: 378092.66 | O7: 73904 | P7: 237320.61 | Q7: 0 | R7: 0 | S7: 3511 | T7: 22363.77 | U7: 6087414 | V7: 10556404 | W7: 3068094 | X7: 4255370.5 | Y7: 6422 | Z7: 102363.19 | AA7: 21419031 | AB7: 99716222 | AC7: 32990 | AD7: 32410.1 | AE7: 637777.04 | AF7: 1.1466277e+08 | AG7: DC High
A8: 32 | B8: 44621 | C8: Public Sector Banks | D8: Indian Overseas Bank | E8: 2742 | F8: 613 | G8: 0 | H8: 0 | I8: 0 | J8: 81152 | K8: 74083 | L8: 20508718 | M8: 59749 | N8: 142499.79 | O8: 26426 | P8: 63550.33 | Q8: 0 | R8: 0 | S8: 867 | T8: 4013.25 | U8: 3664568 | V8: 6294023.6 | W8: 1386870 | X8: 2078848.1 | Y8: 0 | Z8: 0 | AA8: 15137144 | AB8: 64870005 | AC8: 0 | AD8: 0 | AE8: 210063.37 | AF8: 73242877 | AG8: DC High
A9: 43 | B9: 44621 | C9: Public Sector Banks | D9: Punjab & Sind Bank | E9: 657 | F9: 19 | G9: 1091 | H9: 357 | I9: 1159 | J9: 8053 | K9: 0 | L9: 3546410 | M9: 0 | N9: 0 | O9: 0 | P9: 0 | Q9: 0 | R9: 0 | S9: 0 | T9: 0 | U9: 591821 | V9: 1291990.7 | W9: 386245 | X9: 785117.66 | Y9: 0 | Z9: 0 | AA9: 1689903 | AB9: 7692797.8 | AC9: 0 | AD9: 0 | AE9: 0 | AF9: 9769906.2 | AG9: DC High
A10: 44 | B10: 44621 | C10: Public Sector Banks | D10: Punjab National Bank | E10: 8211 | F10: 5143 | G10: 49833 | H10: 11265 | I10: 564726 | J10: 56411 | K10: 327893 | L10: 45957631 | M10: 443277 | N10: 1296879.2 | O10: 180344 | P10: 576375.14 | Q10: 0 | R10: 0 | S10: 3401 | T10: 11026.03 | U10: 9324599 | V10: 18895014 | W10: 5918799 | X10: 8948889.4 | Y10: 0 | Z10: 0 | AA10: 31840380 | AB10: 1.5608157e+08 | AC10: 0 | AD10: 0 | AE10: 1884280.4 | AF10: 1.8392547e+08 | AG10: DC High
A11: 49 | B11: 44621 | C11: Public Sector Banks | D11: State Bank of India | E11: 26189 | F11: 39350 | G11: 924374 | H11: 49913 | I11: 472784 | J11: 1558576 | K11: 13766861 | L11: 275922932 | M11: 22282182 | N11: 67147844 | O11: 20617840 | P11: 1.370341e+08 | Q11: 0 | R11: 0 | S11: 92610 | T11: 340033.62 | U11: 59661111 | V11: 1.1441209e+08 | W11: 33511927 | X11: 54276184 | Y11: 2552 | Z11: 28000.14 | AA11: 194459535 | AB11: 9.6970516e+08 | AC11: 83123 | AD11: 77101.65 | AE11: 2.0452198e+08 | AF11: 1.1384985e+09 | AG11: DC High
A12: 52 | B12: 44621 | C12: Public Sector Banks | D12: UCO Bank | E12: 2095 | F12: 222 | G12: 11223 | H12: 3568 | I12: 1830 | J12: 354332 | K12: 0 | L12: 11300018 | M12: 0 | N12: 0 | O12: 0 | P12: 0 | Q12: 0 | R12: 0 | S12: 0 | T12: 0 | U12: 1838490 | V12: 3647945.5 | W12: 1283322 | X12: 1931029.2 | Y12: 798 | Z12: 12973.65 | AA12: 7004324 | AB12: 30931578 | AC12: 2179 | AD12: 2007.68 | AE12: 0 | AF12: 36525534 | AG12: DC High
A13: 54 | B13: 44621 | C13: Public Sector Banks | D13: Union Bank of India | E13: 8042 | F13: 3190 | G13: 197533 | H13: 8049 | I13: 5591 | J13: 220221 | K13: 538325 | L13: 47932253 | M13: 438865 | N13: 1307558.9 | O13: 282726 | P13: 950075.4 | Q13: 0 | R13: 0 | S13: 3485 | T13: 19392.71 | U13: 10753368 | V13: 18087631 | W13: 7606876 | X13: 10848267 | Y13: 2319 | Z13: 8568.96 | AA13: 49725391 | AB13: 1.5087068e+08 | AC13: 13354 | AD13: 13311.76 | AE13: 2277027 | AF13: 1.7982846e+08 | AG13: DC High
... A517: 2666 | B517: 45901 | C517: Public Sector Banks | D517: Union Bank of India | E517: 7866 | F517: 1196 | G517: 53428 | H517: 8059 | I517: 369473 | J517: 291785 | K517: 475427 | L517: 57201215 | M517: 480574 | N517: 2101137.7 | O517: 1799229 | P517: 3210082.1 | Q517: 0 | R517: 0 | S517: 8731 | T517: 37968.58 | U517: 3588891 | V517: 8505983.9 | W517: 908024 | X517: 2442384.9 | Y517: 2150 | Z517: 8722.95 | AA517: 40386186 | AB517: 1.1880931e+08 | AC517: 11 | AD517: 2.2 | AE517: 5349188.4 | AF517: 1.297664e+08 | AG517: DC High

Sheet Private Sector Banks
A1: ID | B1: Date | C1: Bank_Category | D1: Bank_Name | E1: ATM's Onsite | F1: ATM's Offsite | G1: POS | H1: Micro_ ATM's | I1: Bharath_QR | J1: Upi_QR | K1: Credit_Cards | L1: Debit_Cards | M1: No of CC at POS | N1: Value of CC at POS | O1: No of CC Online Transaction | P1: CC Online Transaction value | Q1: No of other CC Transactions | R1: Value of other CC Transactions | S1: No of Credit CC Withdrawl | T1: Value of CC_Cash Withdrawl | U1: No of DC at POS | V1: Value of DC at POS | W1: No ofDC Online Transaction | X1: Value of DC Online Transaction | Y1: No of other DC Transactions | Z1: Value of other DC Transactions | AA1: No of DC _Cash Withdrawl_ATM | AB1: Value_ DC _Cash Withdrawl_ATM | AC1: No of DC _Cash Withdrawl_POS | AD1: Value_DC _Cash Withdrawl_POS | AE1: CC_Transaction Total Value | AF1: DC_Transaction Total value | AG1: Comparision of CC and DC Total value
A2: 3 | B2: 44621 | C2: Private Sector Banks | D2: Axis Bank | E2: 5748 | F2: 11174 | G2: 1010244 | H2: 710 | I2: 347644 | J2: 36594577 | K2: 9034829 | L2: 27747647 | M2: 13841270 | N2: 41222880 | O2: 9407975 | P2: 52642163 | Q2: 0 | R2: 0 | S2: 45631 | T2: 185105.56 | U2: 12387481 | V2: 27686319 | W2: 6319140 | X2: 18441050 | Y2: 26208 | Z2: 658186.04 | AA2: 22320612 | AB2: 137931664 | AC2: 0 | AD2: 0 | AE2: 94050149 | AF2: 1.8471722e+08 | AG2: DC High
A3: 4 | B3: 44621 | C3: Private Sector Banks | D3: Bandhan Bank | E3: 466 | F3: 5 | G3: 36339 | H3: 0 | I3: 0 | J3: 0 | K3: 0 | L3: 4966096 | M3: 0 | N3: 0 | O3: 0 | P3: 0 | Q3: 0 | R3: 0 | S3: 0 | T3: 0 | U3: 592668 | V3: 1405190 | W3: 394699 | X3: 918313 | Y3: 0 | Z3: 0 | AA3: 2658287 | AB3: 14003767 | AC3: 27811 | AD3: 27834 | AE3: 0 | AF3: 16355104 | AG3: DC High
A4: 12 | B4: 44621 | C4: Private Sector Banks | D4: Catholic Syrian Bank | E4: 1110 | F4: 622 | G4: 0 | H4: 1067 | I4: 3835 | J4: 0 | K4: 0 | L4: 804171 | M4: 0 | N4: 0 | O4: 0 | P4: 0 | Q4: 0 | R4: 0 | S4: 0 | T4: 0 | U4: 248523 | V4: 408223.75 | W4: 59475 | X4: 105540.05 | Y4: 8 | Z4: 24.36 | AA4: 498802 | AB4: 2370432.9 | AC4: 42 | AD4: 28.23 | AE4: 0 | AF4: 2884249.3 | AG4: DC High
A5: 15 | B5: 44621 | C5: Private Sector Banks | D5: City Union Bank | E5: 407 | F5: 52 | G5: 7927 | H5: 20366 | I5: 0 | J5: 29912 | K5: 1834 | L5: 2579284 | M5: 1494 | N5: 4334.4 | O5: 433 | P5: 1626.48 | Q5: 0 | R5: 0 | S5: 8 | T5: 18 | U5: 952999 | V5: 1687005.1 | W5: 257331 | X5: 409040.23 | Y5: 0 | Z5: 0 | AA5: 2757082 | AB5: 14527321 | AC5: 0 | AD5: 0 | AE5: 5978.88 | AF5: 16623366 | AG5: DC High
A6: 17 | B6: 44621 | C6: Private Sector Banks | D6: DCB Bank | E6: 341 | F6: 8 | G6: 8980 | H6: 0 | I6: 4944 | J6: 0 | K6: 3778 | L6: 854723 | M6: 6334 | N6: 13941.52 | O6: 3939 | P6: 14687.33 | Q6: 0 | R6: 0 | S6: 205 | T6: 1475.94 | U6: 273325 | V6: 506682.38 | W6: 98394 | X6: 349894.14 | Y6: 703 | Z6: 25257.51 | AA6: 331189 | AB6: 1951474.8 | AC6: 0 | AD6: 0 | AE6: 30104.79 | AF6: 2833308.8 | AG6: DC High
A7: 19 | B7: 44621 | C7: Private Sector Banks | D7: Dhanlaxmi Bank | E7: 214 | F7: 44 | G7: 1472 | H7: 0 | I7: 0 | J7: 18530 | K7: 7134 | L7: 503775 | M7: 16955 | N7: 34979.61 | O7: 6809 | P7: 18950.62 | Q7: 7 | R7: 33.83 | S7: 120 | T7: 437.69 | U7: 246496 | V7: 393789.86 | W7: 63706 | X7: 105083.91 | Y7: 0 | Z7: 0 | AA7: 464152 | AB7: 2044583.1 | AC7: 0 | AD7: 0 | AE7: 54401.75 | AF7: 2543456.8 | AG7: DC High
A8: 22 | B8: 44621 | C8: Private Sector Banks | D8: Federal Bank | E8: 1505 | F8: 380 | G8: 16569 | H8: 0 | I8: 105113 | J8: 3077952 | K8: 134841 | L8: 11129386 | M8: 280863 | N8: 936308.87 | O8: 381977 | P8: 1532227.5 | Q8: 0 | R8: 0 | S8: 1771 | T8: 9438.67 | U8: 5243651 | V8: 8564523.9 | W8: 2268479 | X8: 4444411 | Y8: 1903 | Z8: 19257.84 | AA8: 9289376 | AB8: 45815354 | AC8: 297 | AD8: 238.25 | AE8: 2477975 | AF8: 58843785 | AG8: DC High
A9: 25 | B9: 44621 | C9: Private Sector Banks | D9: HDFC Bank | E9: 8703 | F9: 9427 | G9: 1071935 | H9: 3324 | I9: 1244660 | J9: 0 | K9: 16536735 | L9: 43041155 | M9: 29331886 | N9: 1.0854418e+08 | O9: 27983613 | P9: 176400101 | Q9: 0 | R9: 0 | S9: 137659 | T9: 854422.64 | U9: 23236053 | V9: 52195451 | W9: 16237685 | X9: 40119274 | Y9: 600176 | Z9: 4278794.7 | AA9: 40385394 | AB9: 2.4297685e+08 | AC9: 27684 | AD9: 27694.29 | AE9: 2.8579871e+08 | AF9: 3.3959806e+08 | AG9: DC High
A10: 27 | B10: 44621 | C10: Private Sector Banks | D10: ICICI Bank | E10: 8402 | F10: 8175 | G10: 944320 | H10: 3693 | I10: 514398 | J10: 3100255 | K10: 12978825 | L10: 36655920 | M10: 19424563 | N10: 69564135 | O10: 23318694 | P10: 137741763 | Q10: 0 | R10: 0 | S10: 48760 | T10: 229472.31 | U10: 17199869 | V10: 40590934 | W10: 7575836 | X10: 24577625 | Y10: 26071 | Z10: 255784.45 | AA10: 24390197 | AB10: 1.5403078e+08 | AC10: 91 | AD10: 58.77 | AE10: 2.0753537e+08 | AF10: 2.1945519e+08 | AG10: DC High
A11: 28 | B11: 44621 | C11: Private Sector Banks | D11: IDBI Bank | E11: 2221 | F11: 1182 | G11: 25385 | H11: 224 | I11: 4738 | J11: 200147 | K11: 41509 | L11: 13042334 | M11: 68252 | N11: 197503.87 | O11: 51093 | P11: 177028.42 | Q11: 0 | R11: 0 | S11: 451 | T11: 2447.23 | U11: 2902263 | V11: 5362691.4 | W11: 1050806 | X11: 1956517.4 | Y11: 0 | Z11: 0 | AA11: 7354059 | AB11: 36485373 | AC11: 532 | AD11: 529.15 | AE11: 376979.52 | AF11: 43805111 | AG11: DC High
A12: 29 | B12: 44621 | C12: Private Sector Banks | D12: IDFC First Bank | E12: 505 | F12: 214 | G12: 26560 | H12: 11522 | I12: 0 | J12: 38079 | K12: 799219 | L12: 4076204 | M12: 1367730 | N12: 4899089.8 | O12: 1325904 | P12: 7584241 | Q12: 0 | R12: 0 | S12: 11799 | T12: 43601.4 | U12: 1414101 | V12: 2015650.3 | W12: 508390 | X12: 1428377.4 | Y12: 0 | Z12: 0 | AA12: 3103785 | AB12: 12878265 | AC12: 0 | AD12: 0 | AE12: 12526932 | AF12: 16322293 | AG12: DC High
A13: 33 | B13: 44621 | C13: Private Sector Banks | D13: IndusInd Bank | E13: 1492 | F13: 1275 | G13: 220160 | H13: 164 | I13: 35908 | J13: 68715 | K13: 1880393 | L13: 6910699 | M13: 2254748 | N13: 10802314 | O13: 2542328 | P13: 45782776 | Q13: 0 | R13: 0 | S13: 18246 | T13: 92623.22 | U13: 1758336 | V13: 3496811.5 | W13: 1170562 | X13: 3541165 | Y13: 1017 | Z13: 83630.76 | AA13: 5623319 | AB13: 27508948 | AC13: 0 | AD13: 0 | AE13: 56677714 | AF13: 34630555 | AG13: CC High
... A157: 445 | B157: 44835 | C157: Private Sector Banks | D157: Kotak Mahindra Bank | E157: 1471 | F157: 1330 | G157: 67575 | H157: 6657 | I157: 34943 | J157: 337033 | K157: 4519524 | L157: 26089134 | M157: 5064512 | N157: 17255089 | O157: 3813782 | P157: 24305707 | Q157: 0 | R157: 0 | S157: 43631 | T157: 163206.5 | U157: 5015030 | V157: 10395548 | W157: 3381103 | X157: 7846138.2 | Y157: 0 | Z157: 0 | AA157: 11540250 | AB157: 53057630 | AC157: 0 | AD157: 0 | AE157: 41724002 | AF157: 71299317 | AG157: DC High
A158: 447 | B158: 44835 | C158: Private Sector Banks | D158: Nainital Bank | G158: 0 | H158: 0 | I158: 0 | J158: 0 | K158: 0 | L158: 192504 | M158: 0 | N158: 0 | O158: 0 | P158: 0 | Q158: 0 | R158: 0 | S158: 0 | T158: 0 | U158: 32159 | V158: 59659.8 | W158: 18674 | X158: 38577.2 | Y158: 0 | Z158: 0 | AA158: 102865 | AB158: 477455.23 | AC158: 37 | AD158: 19.8 | AE158: 0 | AF158: 575712.03 | AG158: DC High
A159: 452 | B159: 44835 | C159: Private Sector Banks | D159: RBL Bank | E159: 373 | F159: 40 | G159: 888964 | H159: 0 | I159: 47297 | J159: 70400 | K159: 4166704 | L159: 1484226 | M159: 7389527 | N159: 29149402 | O159: 3217291 | P159: 25252033 | Q159: 0 | R159: 0 | S159: 40886 | T159: 136326.37 | U159: 323775 | V159: 751689.7 | W159: 128924 | X159: 441068.55 | Y159: 140 | Z159: 5427.8 | AA159: 686124 | AB159: 3418659.8 | AC159: 0 | AD159: 0 | AE159: 54537762 | AF159: 4616845.9 | AG159: CC High
A160: 455 | B160: 44835 | C160: Private Sector Banks | D160: South Indian Bank | E160: 856 | F160: 418 | G160: 13467 | H160: 0 | I160: 5681 | J160: 64275 | K160: 155095 | L160: 3569346 | M160: 411851 | N160: 1378042.3 | O160: 372318 | P160: 2350325 | Q160: 0 | R160: 0 | S160: 0 | T160: 0 | U160: 1805959 | V160: 3309767.3 | W160: 339915 | X160: 901760.93 | Y160: 0 | Z160: 0 | AA160: 3177569 | AB160: 14187834 | AC160: 0 | AD160: 0 | AE160: 3728367.3 | AF160: 18399362 | AG160: DC High
A161: 459 | B161: 44835 | C161: Private Sector Banks | D161: Tamilnad Mercantile Bank | E161: 482 | F161: 667 | G161: 4560 | H161: 0 | I161: 0 | J161: 0 | K161: 40906 | L161: 2135215 | M161: 56179 | N161: 244118.69 | O161: 21197 | P161: 107040.96 | Q161: 0 | R161: 0 | S161: 2221 | T161: 8881.2 | U161: 559926 | V161: 1278185.2 | W161: 99185 | X161: 190753.54 | Y161: 143 | Z161: 369.31 | AA161: 5375814 | AB161: 22909000 | AC161: 0 | AD161: 0 | AE161: 360040.85 | AF161: 24378308 | AG161: DC High
A162: 465 | B162: 44835 | C162: Private Sector Banks | D162: Yes Bank | E162: 1069 | F162: 186 | G162: 59563 | H162: 90252 | I162: 334834 | J162: 127382010 | K162: 1327942 | L162: 3979824 | M162: 2046294 | N162: 6629048.9 | O162: 879132 | P162: 6898359.7 | Q162: 0 | R162: 0 | S162: 18466 | T162: 80469.95 | U162: 1315505 | V162: 2902241 | W162: 589752 | X162: 1564936.5 | Y162: 51 | Z162: 819.64 | AA162: 2917520 | AB162: 13954442 | AC162: 693 | AD162: 692.9 | AE162: 13607878 | AF162: 18423132 | AG162: DC High
A163: 469 | B163: 44866 | C163: Private Sector Banks | D163: Axis Bank | E163: 5761 | F163: 10097 | G163: 1315288 | H163: 847 | I163: 529854 | J163: 48205705 | K163: 9294011 | L163: 28716921 | M163: 17477667 | N163: 53921066 | O163: 11708221 | P163: 50384644 | Q163: 0 | R163: 0 | S163: 63664 | T163: 249091.75 | U163: 9592907 | V163: 22383618 | W163: 4133071 | X163: 12728599 | Y163: 18670 | Z163: 459282.69 | AA163: 20912950 | AB163: 1.2395396e+08 | AC163: 0 | AD163: 0 | AE163: 1.045548e+08 | AF163: 1.5952545e+08 | AG163: DC High
A164: 470 | B164: 44866 | C164: Private Sector Banks | D164: Bandhan Bank | E164: 428 | F164: 5 | G164: 37245 | H164: 0 | I164: 0 | J164: 0 | K164: 0 | L164: 5288593 | M164: 0 | N164: 0 | O164: 0 | P164: 0 | Q164: 0 | R164: 0 | S164: 0 | T164: 0 | U164: 485765 | V164: 1161011.4 | W164: 230431 | X164: 630969.42 | Y164: 0 | Z164: 0 | AA164: 2514793 | AB164: 12884540 | AC164: 27782 | AD164: 28002.22 | AE164: 0 | AF164: 14704523 | AG164: DC High
A165: 476 | B165: 44866 | C165: Private Sector Banks | D165: CSB Bank | E165: 457 | F165: 53 | G165: 0 | H165: 1188 | I165: 5541 | J165: 0 | K165: 0 | L165: 854222 | M165: 0 | N165: 0 | O165: 0 | P165: 0 | Q165: 0 | R165: 0 | S165: 0 | T165: 0 | U165: 231125 | V165: 392185.54 | W165: 34067 | X165: 68857.44 | Y165: 12 | Z165: 120 | AA165: 792782 | AB165: 2947232.2 | AC165: 17 | AD165: 15.26 | AE165: 0 | AF165: 3408410.4 | AG165: DC High
A166: 481 | B166: 44866 | C166: Private Sector Banks | D166: City Union Bank | E166: 1108 | F166: 568 | G166: 7050 | H166: 29521 | I166: 0 | J166: 43655 | K166: 1942 | L166: 2673773 | M166: 1678 | N166: 3411.06 | O166: 451 | P166: 1819.71 | Q166: 0 | R166: 0 | S166: 8 | T166: 23.5 | U166: 776889 | V166: 1488179.1 | W166: 128671 | X166: 269982.93 | Y166: 0 | Z166: 0 | AA166: 2566297 | AB166: 13122310 | AC166: 0 | AD166: 0 | AE166: 5254.27 | AF166: 14880472 | AG166: DC High
A167: 483 | B167: 44866 | C167: Private Sector Banks | D167: DCB Bank | E167: 375 | F167: 8 | G167: 8839 | H167: 0 | I167: 6719 | J167: 0 | K167: 0 | L167: 941387 | M167: 0 | N167: 0 | O167: 0 | P167: 0 | Q167: 0 | R167: 0 | S167: 0 | T167: 0 | U167: 145602 | V167: 340709.73 | W167: 31462 | X167: 125894.66 | Y167: 373 | Z167: 11413.81 | AA167: 275551 | AB167: 1517058 | AC167: 0 | AD167: 0 | AE167: 0 | AF167: 1995076.2 | AG167: DC High
A168: 485 | B168: 44866 | C168: Private Sector Banks | D168: Dhanlaxmi Bank | E168: 222 | F168: 42 | G168: 1457 | H168: 0 | I168: 0 | J168: 25223 | K168: 8434 | L168: 525552 | M168: 20316 | N168: 40638.94 | O168: 5548 | P168: 18149.69 | Q168: 0 | R168: 0 | S168: 154 | T168: 493.3 | U168: 241858 | V168: 373185.9 | W168: 23485 | X168: 55678.5 | Y168: 0 | Z168: 0 | AA168: 462412 | AB168: 1988713.4 | AC168: 0 | AD168: 0 | AE168: 59281.93 | AF168: 2417577.9 | AG168: DC High
A169: 488 | B169: 44866 | C169: Private Sector Banks | D169: Federal Bank | E169: 1535 | F169: 351 | G169: 16406 | H169: 0 | I169: 80792 | J169: 3780983 | K169: 407760 | L169: 12575237 | M169: 835580 | N169: 2623851.9 | O169: 853081 | P169: 4808479.9 | Q169: 0 | R169: 0 | S169: 3513 | T169: 15054 | U169: 4886063 | V169: 8414520.8 | W169: 1709588 | X169: 4412955.9 | Y169: 2361 | Z169: 28830.35 | AA169: 8895741 | AB169: 42717015 | AC169: 227 | AD169: 198.23 | AE169: 7447385.8 | AF169: 55573520 | AG169: DC High
A170: 491 | B170: 44866 | C170: Private Sector Banks | D170: HDFC Bank | E170: 9366 | F170: 9530 | G170: 1516998 | H170: 4232 | I170: 1528839 | J170: 0 | K170: 16782602 | L170: 48725677 | M170: 31012334 | N170: 1.2150015e+08 | O170: 27100862 | P170: 2.0499802e+08 | Q170: 0 | R170: 0 | S170: 195216 | T170: 1128407.1 | U170: 21235564 | V170: 53001141 | W170: 13971203 | X170: 38589577 | Y170: 117767 | Z170: 1849620.8 | AA170: 39673982 | AB170: 2.3779817e+08 | AC170: 55852 | AD170: 55919.01 | AE170: 3.2762658e+08 | AF170: 3.3129443e+08 | AG170: DC High
... A178: 505 | B178: 44866 | C178: Private Sector Banks | D178: Kotak Mahindra Bank | E178: 1471 | F178: 1330 | G178: 69993 | H178: 6762 | I178: 42107 | J178: 354132 | K178: 4597686 | L178: 26514365 | M178: 4773570 | N178: 15021328 | O178: 3656661 | P178: 22481454 | Q178: 0 | R178: 0 | S178: 46473 | T178: 164141.95 | U178: 4148561 | V178: 7828807.2 | W178: 2951836 | X178: 6695356 | Y178: 0 | Z178: 0 | AA178: 10359897 | AB178: 47537324 | AC178: 0 | AD178: 0 | AE178: 37666923 | AF178: 62061487 | AG178: DC High
A179: 507 | B179: 44866 | C179: Private Sector Banks | D179: Nainital Bank | G179: 0 | H179: 0 | I179: 0 | J179: 0 | K179: 0 | L179: 195401 | M179: 0 | N179: 0 | O179: 0 | P179: 0 | Q179: 0 | R179: 0 | S179: 0 | T179: 0 | U179: 29487 | V179: 54216.44 | W179: 16603 | X179: 33234.85 | Y179: 0 | Z179: 0 | AA179: 92976 | AB179: 428257.23 | AC179: 27 | AD179: 11.7 | AE179: 0 | AF179: 515720.22 | AG179: DC High
A180: 512 | B180: 44866 | C180: Private Sector Banks | D180: RBL Bank | E180: 373 | F180: 40 | G180: 897075 | H180: 0 | I180: 47333 | J180: 72005 | K180: 4230404 | L180: 1512891 | M180: 6804218 | N180: 26533498 | O180: 2983772 | P180: 23407564 | Q180: 0 | R180: 0 | S180: 42534 | T180: 136334.41 | U180: 276063 | V180: 593186.17 | W180: 121881 | X180: 441191.04 | Y180: 106 | Z180: 3591.73 | AA180: 616441 | AB180: 3072461.5 | AC180: 0 | AD180: 0 | AE180: 50077397 | AF180: 4110430.4 | AG180: CC High
A181: 515 | B181: 44866 | C181: Private Sector Banks | D181: South Indian Bank | E181: 856 | F181: 418 | G181: 13759 | H181: 0 | I181: 6086 | J181: 65348 | K181: 169154 | L181: 3600077 | M181: 403676 | N181: 1285959.5 | O181: 381813 | P181: 2532363.2 | Q181: 0 | R181: 0 | S181: 0 | T181: 0 | U181: 1659353 | V181: 2992962.9 | W181: 301406 | X181: 821144.5 | Y181: 0 | Z181: 0 | AA181: 3063923 | AB181: 13671496 | AC181: 0 | AD181: 0 | AE181: 3818322.7 | AF181: 17485603 | AG181: DC High
A182: 519 | B182: 44866 | C182: Private Sector Banks | D182: Tamilnad Mercantile Bank | E182: 482 | F182: 667 | G182: 4662 | H182: 0 | I182: 0 | J182: 0 | K182: 40992 | L182: 2150529 | M182: 57427 | N182: 243277.91 | O182: 21169 | P182: 106915.35 | Q182: 0 | R182: 0 | S182: 2323 | T182: 9314.8 | U182: 429367 | V182: 892372.07 | W182: 99435 | X182: 195653.63 | Y182: 97 | Z182: 281.5 | AA182: 4943348 | AB182: 20394752 | AC182: 0 | AD182: 0 | AE182: 359508.06 | AF182: 21483060 | AG182: DC High
A183: 526 | B183: 44866 | C183: Private Sector Banks | D183: Yes Bank | E183: 1069 | F183: 186 | G183: 60986 | H183: 91482 | I183: 342577 | J183: 130186487 | K183: 1361789 | L183: 4075864 | M183: 1908458 | N183: 6097833.7 | O183: 845235 | P183: 6790707.7 | Q183: 0 | R183: 0 | S183: 19314 | T183: 86113.2 | U183: 1129361 | V183: 2325716.7 | W183: 523061 | X183: 1442814.7 | Y183: 56 | Z183: 942.65 | AA183: 2698249 | AB183: 12676077 | AC183: 749 | AD183: 744.45 | AE183: 12974655 | AF183: 16446295 | AG183: DC High
A184: 530 | B184: 44896 | C184: Private Sector Banks | D184: Axis Bank | E184: 5791 | F184: 9851 | G184: 1347823 | H184: 847 | I184: 544192 | J184: 51048928 | K184: 9443017 | L184: 28759959 | M184: 19157977 | N184: 59109720 | O184: 12568657 | P184: 54408027 | Q184: 0 | R184: 0 | S184: 65696 | T184: 264625.38 | U184: 10065773 | V184: 23897863 | W184: 4140972 | X184: 13352164 | Y184: 19125 | Z184: 473137.47 | AA184: 21269839 | AB184: 131229103 | AC184: 0 | AD184: 0 | AE184: 1.1378237e+08 | AF184: 1.6895227e+08 | AG184: DC High
A185: 531 | B185: 44896 | C185: Private Sector Banks | D185: Bandhan Bank | E185: 407 | F185: 5 | G185: 37746 | H185: 0 | I185: 0 | J185: 0 | K185: 0 | L185: 5267927 | M185: 0 | N185: 0 | O185: 0 | P185: 0 | Q185: 0 | R185: 0 | S185: 0 | T185: 0 | U185: 488987 | V185: 1187265.4 | W185: 225143 | X185: 650015.78 | Y185: 0 | Z185: 0 | AA185: 2591262 | AB185: 13344636 | AC185: 29060 | AD185: 28675.47 | AE185: 0 | AF185: 15210592 | AG185: DC High
A186: 537 | B186: 44896 | C186: Private Sector Banks | D186: CSB Bank | E186: 459 | F186: 53 | G186: 0 | H186: 1187 | I186: 5665 | J186: 0 | K186: 158 | L186: 864160 | M186: 151 | N186: 173.12 | O186: 67 | P186: 80.1 | Q186: 0 | R186: 0 | S186: 0 | T186: 0 | U186: 263950 | V186: 474334.24 | W186: 33701 | X186: 70480.06 | Y186: 16 | Z186: 126 | AA186: 541028 | AB186: 2506557.1 | AC186: 21 | AD186: 13.1 | AE186: 253.22 | AF186: 3051510.6 | AG186: DC High
A187: 542 | B187: 44896 | C187: Private Sector Banks | D187: City Union Bank | E187: 1115 | F187: 564 | G187: 7046 | H187: 30882 | I187: 0 | J187: 42205 | K187: 2588 | L187: 2699516 | M187: 2494 | N187: 5197.84 | O187: 722 | P187: 2568.77 | Q187: 0 | R187: 0 | S187: 4 | T187: 11 | U187: 817302 | V187: 1617601.5 | W187: 132261 | X187: 278496.97 | Y187: 0 | Z187: 0 | AA187: 2727528 | AB187: 14015663 | AC187: 0 | AD187: 0 | AE187: 7777.61 | AF187: 15911761 | AG187: DC High
A188: 544 | B188: 44896 | C188: Private Sector Banks | D188: DCB Bank | E188: 378 | F188: 7 | G188: 8785 | H188: 0 | I188: 6850 | J188: 0 | K188: 0 | L188: 947232 | M188: 0 | N188: 0 | O188: 0 | P188: 0 | Q188: 0 | R188: 0 | S188: 0 | T188: 0 | U188: 151617 | V188: 381351.94 | W188: 31456 | X188: 133113.52 | Y188: 399 | Z188: 13751.43 | AA188: 282705 | AB188: 1586500.8 | AC188: 0 | AD188: 0 | AE188: 0 | AF188: 2114717.7 | AG188: DC High
A189: 546 | B189: 44896 | C189: Private Sector Banks | D189: Dhanlaxmi Bank | E189: 223 | F189: 42 | G189: 1477 | H189: 0 | I189: 0 | J189: 25960 | K189: 8635 | L189: 531589 | M189: 21732 | N189: 45305.17 | O189: 5655 | P189: 17605.28 | Q189: 16 | R189: 43.74 | S189: 167 | T189: 503.4 | U189: 260770 | V189: 415755.68 | W189: 22946 | X189: 57938.67 | Y189: 0 | Z189: 0 | AA189: 490695 | AB189: 2088290.1 | AC189: 0 | AD189: 0 | AE189: 63457.59 | AF189: 2561984.5 | AG189: DC High
A190: 549 | B190: 44896 | C190: Private Sector Banks | D190: Federal Bank | E190: 1544 | F190: 350 | G190: 17976 | H190: 0 | I190: 72715 | J190: 3835840 | K190: 452399 | L190: 12017050 | M190: 1038034 | N190: 3227897.4 | O190: 1048993 | P190: 5708597.3 | Q190: 0 | R190: 0 | S190: 3842 | T190: 16586.4 | U190: 5023881 | V190: 8845614.1 | W190: 1655256 | X190: 4099394 | Y190: 2420 | Z190: 29777.28 | AA190: 9390056 | AB190: 45594552 | AC190: 249 | AD190: 202.74 | AE190: 8953081.1 | AF190: 58569541 | AG190: DC High
...

Sheet Foreign Banks
A1: ID | B1: Date | C1: Bank_Category | D1: Bank_Name | E1: ATM's Onsite | F1: ATM's Offsite | G1: POS | H1: Micro_ ATM's | I1: Bharath_QR | J1: Upi_QR | K1: Credit_Cards | L1: Debit_Cards | M1: No of CC at POS | N1: Value of CC at POS | O1: No of CC Online Transaction | P1: CC Online Transaction value | Q1: No of other CC Transactions | R1: Value of other CC Transactions | S1: No of Credit CC Withdrawl | T1: Value of CC_Cash Withdrawl | U1: No of DC at POS | V1: Value of DC at POS | W1: No ofDC Online Transaction | X1: Value of DC Online Transaction | Y1: No of other DC Transactions | Z1: Value of other DC Transactions | AA1: No of DC _Cash Withdrawl_ATM | AB1: Value_ DC _Cash Withdrawl_ATM | AC1: No of DC _Cash Withdrawl_POS | AD1: Value_DC _Cash Withdrawl_POS | AE1: CC_Transaction Total Value | AF1: DC_Transaction Total value | AG1: Comparision of CC and DC Total value
A2: 2 | B2: 44621 | C2: Foreign Banks | D2: American Express | E2: 0 | F2: 0 | G2: 45455 | H2: 0 | I2: 0 | J2: 0 | K2: 1383221 | L2: 0 | M2: 1018513 | N2: 7369321.3 | O2: 3595970 | P2: 25400772 | Q2: 0 | R2: 0 | S2: 0 | T2: 0 | U2: 0 | V2: 0 | W2: 0 | X2: 0 | Y2: 0 | Z2: 0 | AA2: 0 | AB2: 0 | AC2: 0 | AD2: 0 | AE2: 32770093 | AF2: 0 | AG2: CC High
A3: 5 | B3: 44621 | C3: Foreign Banks | D3: Bank of America | E3: 0 | F3: 0 | G3: 0 | H3: 0 | I3: 0 | J3: 0 | K3: 21756 | L3: 0 | M3: 27052 | N3: 99065.02 | O3: 12329 | P3: 107630.45 | Q3: 0 | R3: 0 | S3: 0 | T3: 0 | U3: 0 | V3: 0 | W3: 0 | X3: 0 | Y3: 0 | Z3: 0 | AA3: 0 | AB3: 0 | AC3: 0 | AD3: 0 | AE3: 206695.47 | AF3: 0 | AG3: CC High
A4: 9 | B4: 44621 | C4: Foreign Banks | D4: Barclays Bank | E4: 0 | F4: 0 | G4: 0 | H4: 0 | I4: 1 | J4: 0 | K4: 0 | L4: 1736 | M4: 0 | N4: 0 | O4: 0 | P4: 0 | Q4: 0 | R4: 0 | S4: 0 | T4: 0 | U4: 100 | V4: 907.05 | W4: 32 | X4: 28.32 | Y4: 0 | Z4: 0 | AA4: 401 | AB4: 3499.95 | AC4: 0 | AD4: 0 | AE4: 0 | AF4: 4435.32 | AG4: DC High
A5: 14 | B5: 44621 | C5: Foreign Banks | D5: Citibank | E5: 47 | F5: 441 | G5: 0 | H5: 0 | I5: 0 | J5: 0 | K5: 2551485 | L5: 1432288 | M5: 6782388 | N5: 18646347 | O5: 6258303 | P5: 25148092 | Q5: 0 | R5: 0 | S5: 12658 | T5: 74745.2 | U5: 1028885 | V5: 2400201.5 | W5: 1115035 | X5: 3027062.3 | Y5: 0 | Z5: 0 | AA5: 1006987 | AB5: 5649930.3 | AC5: 0 | AD5: 0 | AE5: 43869184 | AF5: 11077194 | AG5: CC High
A6: 16 | B6: 44621 | C6: Foreign Banks | D6: DBS Bank | E6: 498 | F6: 518 | G6: 1013 | H6: 124 | I6: 0 | J6: 2587 | K6: 1000 | L6: 2125772 | M6: 1479 | N6: 3546.47 | O6: 634 | P6: 2696.69 | Q6: 0 | R6: 0 | S6: 2 | T6: 3 | U6: 729424 | V6: 993395.75 | W6: 356248 | X6: 576736.1 | Y6: 568 | Z6: 7453.43 | AA6: 1326776 | AB6: 5831994.2 | AC6: 50 | AD6: 37.75 | AE6: 6246.16 | AF6: 7409617.2 | AG6: DC High
A7: 18 | B7: 44621 | C7: Foreign Banks | D7: Deutsche Bank | E7: 13 | F7: 19 | G7: 0 | H7: 0 | I7: 0 | J7: 7 | K7: 0 | L7: 121093 | M7: 0 | N7: 0 | O7: 0 | P7: 0 | Q7: 0 | R7: 0 | S7: 0 | T7: 0 | U7: 61475 | V7: 157090.22 | W7: 39416 | X7: 97802.4 | Y7: 0 | Z7: 0 | AA7: 52600 | AB7: 303832.34 | AC7: 0 | AD7: 0 | AE7: 0 | AF7: 558724.96 | AG7: DC High
A8: 26 | B8: 44621 | C8: Foreign Banks | D8: HSBC | E8: 46 | F8: 28 | G8: 0 | H8: 0 | I8: 0 | J8: 0 | K8: 796103 | L8: 515764 | M8: 613458 | N8: 3579623.9 | O8: 1155380 | P8: 3986352.9 | Q8: 0 | R8: 0 | S8: 1675 | T8: 13692.73 | U8: 402555 | V8: 1086459.3 | W8: 0 | X8: 0 | Y8: 0 | Z8: 0 | AA8: 281463 | AB8: 1622205.2 | AC8: 0 | AD8: 0 | AE8: 7579669.4 | AF8: 2708664.5 | AG8: CC High
A9: 46 | B9: 44621 | C9: Foreign Banks | D9: SBM Bank India | E9: 6 | F9: 0 | G9: 0 | H9: 165938 | I9: 0 | J9: 0 | K9: 562051 | L9: 52011 | M9: 341577 | N9: 1609612.9 | O9: 1047799 | P9: 4479465.3 | Q9: 0 | R9: 0 | S9: 108845 | T9: 681013.08 | U9: 2361 | V9: 6405.41 | W9: 5323 | X9: 12178.33 | Y9: 0 | Z9: 0 | AA9: 5486 | AB9: 20899.04 | AC9: 0 | AD9: 0 | AE9: 6770091.2 | AF9: 39482.78 | AG9: CC High
A10: 48 | B10: 44621 | C10: Foreign Banks | D10: Standard Chartered Bank | E10: 91 | F10: 76 | G10: 0 | H10: 0 | I10: 0 | J10: 0 | K10: 1342023 | L10: 1113075 | M10: 1721399 | N10: 5352945 | O10: 1554924 | P10: 6943036.7 | Q10: 0 | R10: 0 | S10: 3205 | T10: 20576.2 | U10: 938238 | V10: 2179490.5 | W10: 735985 | X10: 1315377.8 | Y10: 39 | Z10: 838.2 | AA10: 1099928 | AB10: 5185318.1 | AC10: 0 | AD10: 0 | AE10: 12316558 | AF10: 8681024.6 | AG10: CC High
A11: 60 | B11: 44652 | C11: Foreign Banks | D11: American Express | E11: 0 | F11: 0 | G11: 46662 | H11: 0 | I11: 0 | J11: 0 | K11: 1375307 | L11: 0 | M11: 1048953 | N11: 7532832.5 | O11: 3345816 | P11: 23437612 | Q11: 0 | R11: 0 | S11: 0 | T11: 0 | U11: 0 | V11: 0 | W11: 0 | X11: 0 | Y11: 0 | Z11: 0 | AA11: 0 | AB11: 0 | AC11: 0 | AD11: 0 | AE11: 30970445 | AF11: 0 | AG11: CC High
A12: 63 | B12: 44652 | C12: Foreign Banks | D12: Bank of America | E12: 0 | F12: 0 | G12: 0 | H12: 0 | I12: 0 | J12: 0 | K12: 21588 | L12: 0 | M12: 26619 | N12: 109051.56 | O12: 13355 | P12: 129305.23 | Q12: 0 | R12: 0 | S12: 2 | T12: 20 | U12: 0 | V12: 0 | W12: 0 | X12: 0 | Y12: 0 | Z12: 0 | AA12: 0 | AB12: 0 | AC12: 0 | AD12: 0 | AE12: 238376.79 | AF12: 0 | AG12: CC High
A13: 67 | B13: 44652 | C13: Foreign Banks | D13: Barclays Bank | E13: 0 | F13: 0 | G13: 0 | H13: 0 | I13: 1 | J13: 0 | K13: 0 | L13: 1702 | M13: 0 | N13: 0 | O13: 0 | P13: 0 | Q13: 0 | R13: 0 | S13: 0 | T13: 0 | U13: 61 | V13: 729.73 | W13: 39 | X13: 36.96 | Y13: 0 | Z13: 0 | AA13: 392 | AB13: 3565.09 | AC13: 0 | AD13: 0 | AE13: 0 | AF13: 4331.78 | AG13: DC High
... A35: 200 | B35: 44713 | C35: Foreign Banks | D35: HSBC | E35: 46 | F35: 28 | G35: 0 | H35: 0 | I35: 0 | J35: 0 | K35: 762412 | L35: 523995 | M35: 610907 | N35: 3335531.6 | O35: 1066791 | P35: 3913692.8 | Q35: 0 | R35: 0 | S35: 1666 | T35: 13312.44 | U35: 379483 | V35: 1035718.1 | W35: 0 | X35: 0 | Y35: 0 | Z35: 0 | AA35: 254181 | AB35: 1437561.6 | AC35: 0 | AD35: 0 | AE35: 7262536.8 | AF35: 2473279.7 | AG35: CC High
A36: 220 | B36: 44713 | C36: Foreign Banks | D36: SBM Bank India | E36: 8 | G36: 0 | H36: 230651 | I36: 0 | J36: 0 | K36: 1048914 | L36: 112254 | M36: 374874 | N36: 1534763.9 | O36: 1089788 | P36: 4650711 | Q36: 0 | R36: 0 | S36: 61730 | T36: 399816.32 | U36: 5590 | V36: 10527.47 | W36: 14985 | X36: 26624.95 | Y36: 0 | Z36: 0 | AA36: 6063 | AB36: 24060.15 | AC36: 0 | AD36: 0 | AE36: 6585291.3 | AF36: 61212.57 | AG36: CC High
A37: 222 | B37: 44713 | C37: Foreign Banks | D37: Standard Chartered Bank | E37: 97 | F37: 71 | G37: 0 | H37: 0 | I37: 0 | J37: 0 | K37: 1325750 | L37: 1124313 | M37: 1676090 | N37: 5045067.2 | O37: 1404270 | P37: 6328385 | Q37: 0 | R37: 0 | S37: 3087 | T37: 21310.32 | U37: 850733 | V37: 2056009.4 | W37: 597666 | X37: 1084012.4 | Y37: 21 | Z37: 458.12 | AA37: 969371 | AB37: 4492253.6 | AC37: 0 | AD37: 0 | AE37: 11394763 | AF37: 7632733.6 | AG37: CC High
A38: 234 | B38: 44743 | C38: Foreign Banks | D38: American Express | E38: 0 | F38: 0 | G38: 47948 | H38: 0 | I38: 0 | J38: 0 | K38: 1356420 | L38: 0 | M38: 1005261 | N38: 7204702.3 | O38: 3246269 | P38: 22976106 | Q38: 0 | R38: 0 | S38: 0 | T38: 0 | U38: 0 | V38: 0 | W38: 0 | X38: 0 | Y38: 0 | Z38: 0 | AA38: 0 | AB38: 0 | AC38: 0 | AD38: 0 | AE38: 30180808 | AF38: 0 | AG38: CC High
A39: 237 | B39: 44743 | C39: Foreign Banks | D39: Bank of America | E39: 0 | F39: 0 | G39: 0 | H39: 0 | I39: 0 | J39: 0 | K39: 21092 | L39: 0 | M39: 29471 | N39: 125099.09 | O39: 13528 | P39: 171900.58 | Q39: 0 | R39: 0 | S39: 1 | T39: 10 | U39: 0 | V39: 0 | W39: 0 | X39: 0 | Y39: 0 | Z39: 0 | AA39: 0 | AB39: 0 | AC39: 0 | AD39: 0 | AE39: 297009.67 | AF39: 0 | AG39: CC High
A40: 241 | B40: 44743 | C40: Foreign Banks | D40: Barclays Bank | E40: 0 | F40: 0 | G40: 0 | H40: 0 | I40: 1 | J40: 0 | K40: 0 | L40: 1645 | M40: 0 | N40: 0 | O40: 0 | P40: 0 | Q40: 0 | R40: 0 | S40: 0 | T40: 0 | U40: 50 | V40: 211.54 | W40: 19 | X40: 14.13 | Y40: 0 | Z40: 0 | AA40: 395 | AB40: 3554.5 | AC40: 0 | AD40: 0 | AE40: 0 | AF40: 3780.17 | AG40: DC High
A41: 246 | B41: 44743 | C41: Foreign Banks | D41: Citibank | E41: 47 | F41: 439 | G41: 0 | H41: 0 | I41: 0 | J41: 0 | K41: 2545671 | L41: 1333354 | M41: 6427826 | N41: 17346416 | O41: 5721055 | P41: 24657323 | Q41: 0 | R41: 0 | S41: 10881 | T41: 64539.5 | U41: 972795 | V41: 2416645.8 | W41: 988675 | X41: 2907840.2 | Y41: 0 | Z41: 0 | AA41: 873389 | AB41: 4901371.1 | AC41: 0 | AD41: 0 | AE41: 42068279 | AF41: 10225857 | AG41: CC High
A42: 248 | B42: 44743 | C42: Foreign Banks | D42: DBS Bank | E42: 453 | F42: 515 | G42: 389 | H42: 99 | I42: 0 | J42: 2400 | K42: 34686 | L42: 2038403 | M42: 33022 | N42: 113664.89 | O42: 22266 | P42: 167807.91 | Q42: 0 | R42: 0 | S42: 305 | T42: 991.63 | U42: 649780 | V42: 952846.37 | W42: 262948 | X42: 483032.69 | Y42: 441 | Z42: 7276.32 | AA42: 1198505 | AB42: 5324917 | AC42: 55 | AD42: 47.91 | AE42: 282464.43 | AF42: 6768120.3 | AG42: DC High
A43: 250 | B43: 44743 | C43: Foreign Banks | D43: Deutsche Bank | E43: 13 | F43: 18 | G43: 0 | H43: 0 | I43: 0 | J43: 6 | K43: 0 | L43: 121353 | M43: 0 | N43: 0 | O43: 0 | P43: 0 | Q43: 0 | R43: 0 | S43: 0 | T43: 0 | U43: 66553 | V43: 163656.94 | W43: 26256 | X43: 77109.09 | Y43: 0 | Z43: 0 | AA43: 48481 | AB43: 275393.6 | AC43: 0 | AD43: 0 | AE43: 0 | AF43: 516159.63 | AG43: DC High
A44: 258 | B44: 44743 | C44: Foreign Banks | D44: HSBC | E44: 46 | F44: 28 | G44: 0 | H44: 0 | I44: 0 | J44: 0 | K44: 762067 | L44: 530747 | M44: 664528 | N44: 3621771.8 | O44: 1055283 | P44: 3878482.8 | Q44: 0 | R44: 0 | S44: 1503 | T44: 11525.14 | U44: 383322 | V44: 1095028.9 | W44: 0 | X44: 0 | Y44: 0 | Z44: 0 | AA44: 254073 | AB44: 1457471.4 | AC44: 0 | AD44: 0 | AE44: 7511779.7 | AF44: 2552500.3 | AG44: CC High
A45: 278 | B45: 44743 | C45: Foreign Banks | D45: SBM Bank India | E45: 8 | F45: 0 | G45: 0 | H45: 230651 | I45: 0 | J45: 0 | K45: 1275573 | L45: 134661 | M45: 510945 | N45: 2386880.2 | O45: 1429038 | P45: 7030080.5 | Q45: 0 | R45: 0 | S45: 66276 | T45: 410729.18 | U45: 7516 | V45: 15774.66 | W45: 20762 | X45: 42366.5 | Y45: 0 | Z45: 0 | AA45: 13762 | AB45: 54053.94 | AC45: 0 | AD45: 0 | AE45: 9827689.9 | AF45: 112195.1 | AG45: CC High
A46: 280 | B46: 44743 | C46: Foreign Banks | D46: Standard Chartered Bank | E46: 99 | F46: 73 | G46: 0 | H46: 0 | I46: 0 | J46: 0 | K46: 1321772 | L46: 1166145 | M46: 1617835 | N46: 4840811.7 | O46: 1381403 | P46: 6461999 | Q46: 0 | R46: 0 | S46: 2744 | T46: 18453.68 | U46: 911279 | V46: 2192401.9 | W46: 546969 | X46: 1141747.9 | Y46: 35 | Z46: 622.65 | AA46: 1001958 | AB46: 4676411.5 | AC46: 0 | AD46: 0 | AE46: 11321264 | AF46: 8011183.9 | AG46: CC High
